<?xml version="1.0"?>
<robot name="RAPID" xmlns:xacro="http://www.ros.org/wiki/xacro" >

    <!-- UNITS: Metric units for everything. Kilograms for mass and Meters for length -->

    <!-- <xacro:include filename="inertial_macros.xacro"/> -->

    <material name="white">
        <color rgba="1 1 1 1" />
    </material>

    <material name="black">
        <color rgba="0.25 0.25 0.25 1"/>
    </material>

    <material name="red">
        <color rgba="1 0 0 1"/>
    </material>

    <material name="gray">
        <color rgba="0.8 0.8 0.8 1"/>
    </material>

    <material name="gold">
        <color rgba="1 0.84 0 1"/>
    </material>

    <!-- BASE LINK -->

    <link name="base_link">

    </link>

    <!-- BASE_FOOTPRINT LINK -->

    <joint name="base_footprint_joint" type="fixed">
        <parent link="base_link"/>
        <child link="base_footprint"/>
        <origin xyz="0 0 0" rpy="0 0 0"/>
    </joint>

    <link name="base_footprint">
    </link>


    <!-- CHASSIS BASE LINK -->

    <joint name="chassis_base_joint" type="fixed">
        <parent link="base_link"/>
        <child link="chassis_base"/>
        <!-- change this so that the origin is on the complete back wall -->
        <origin xyz="-0.291465 0 -0.026035"/>
    </joint>

    <link name="chassis_base">
        <visual>
            <origin xyz="0.1778 0 0.06985"/>
            <geometry>
                <box size="0.3556 0.2032 0.1397"/>
            </geometry>
            <material name="black"/>
        </visual>
        <collision>
            <origin xyz="0.1778 0 0.06985"/>
            <geometry>
                <box size="0.3556 0.2032 0.1397"/>
            </geometry>
        </collision>
        <!-- <xacro:inertial_box mass="0.5" x="0.3556" y="0.2032" z="0.1397"> -->
            <!-- origin should match visual origin -->
            <!-- <origin xyz="0.1778 0 0.06985" rpy="0 0 0"/> 
        </xacro:inertial_box> -->
    </link>

    <gazebo reference="chassis_base">
        <material>Gazebo/Black</material>
    </gazebo>

    <!-- CHASSIS TOP LINK -->

    <joint name="chassis_top_joint" type="fixed">
        <origin xyz="0.1778 0 0.1397" rpy="0 0 0" />
        <parent link="chassis_base"/>
        <child link="chassis_top"/>
    </joint>

    <link name="chassis_top">
        <visual>
            <origin xyz="0 0 0.09525"/>
            <geometry>
                <box size="0.4064 0.254 0.1905" />
            </geometry>
            <material name="gold" />
        </visual>
        <collision>
            <origin xyz="0 0 0" rpy="0 0 0" />
            <geometry>
                <box size="0.4064 0.254 0.1905" />
            </geometry>
        </collision>
    </link>

    <gazebo reference="chassis_top">
        <material>Gazebo/Gold</material>
    </gazebo>

    <!-- LID LINK -->

    <joint name="lid_joint" type="fixed">
        <origin xyz="0 0 0.1905" />
        <parent link="chassis_top"/>
        <child link="lid"/>
    </joint>

    <link name="lid">
        <visual>
            <origin xyz="0 0 0.0127" />
            <geometry>
                <box size="0.4064 0.254 0.0254" />
            </geometry>
            <material name="black" />
        </visual>
        <collision>
            <origin xyz="0 0 0.0254" />
            <geometry>
                <box size="0.4064 0.254 0.0254" />
            </geometry>
        </collision>
    </link>

    <gazebo reference="lid">
        <material>Gazebo/Black</material>
    </gazebo>

    <!-- BACK LEFT WHEEL LINK -->

    <joint name="back_left_wheel_joint" type="continuous">
        <parent link="base_link"/>
        <child link="back_left_wheel"/>
        <origin xyz="0 0.1143 0" rpy="-1.5707963267948966 0 0" />
        <axis xyz="0 0 1"/>
    </joint>

    <link name="back_left_wheel">
        <visual>
            <geometry>
                <cylinder radius="0.0762" length="0.0254"/>
            </geometry>
            <material name="gray"/>
        </visual>
        <collision>
            <geometry>
                <sphere radius="0.0762"/>
            </geometry>
        </collision>
        <!-- <xacro:inertial_cylinder mass="0.05" length="0.0254" radius="0.0762"> -->
            <!-- origin should match visual origin -->
            <!-- <origin xyz="0 0 0" rpy="0 0 0"/>
        </xacro:inertial_cylinder> -->
    </link>

    <gazebo reference="back_left_wheel">
        <material>Gazebo/Gray</material>
    </gazebo>

    <!-- FRONT LEFT WHEEL LINK -->

    <joint name="front_left_wheel_joint" type="continuous">
        <parent link="base_link"/>
        <child link="front_left_wheel"/>
        <origin xyz="-0.22733 0.1143 0" rpy="-1.5707963267948966 0 0" />
        <axis xyz="0 0 1"/>
    </joint>

    <link name="front_left_wheel">
        <visual>
            <geometry>
                <cylinder radius="0.0762" length="0.0254"/>
            </geometry>
            <material name="gray"/>
        </visual>
        <collision>
            <geometry>
                <sphere radius="0.0762"/>
            </geometry>
        </collision>
        <!-- <xacro:inertial_cylinder mass="0.05" length="0.0254" radius="0.0762"> -->
            <!-- origin should match visual origin -->
            <!-- <origin xyz="0 0 0" rpy="0 0 0"/>
        </xacro:inertial_cylinder> -->
    </link>

    <gazebo reference="front_left_wheel">
        <material>Gazebo/Gray</material>
    </gazebo>

    <!-- BACK RIGHT WHEEL LINK -->

    <joint name="back_right_wheel_joint" type="continuous">
        <parent link="base_link"/>
        <child link="back_right_wheel"/>
        <origin xyz="0 -0.1143 0" rpy="1.5707963267948966 0 0" />
        <axis xyz="0 0 -1"/>
    </joint>

    <link name="back_right_wheel">
        <visual>
            <geometry>
                <cylinder radius="0.0762" length="0.0254"/>
            </geometry>
            <material name="gray"/>
        </visual>
        <collision>
            <geometry>
                <sphere radius="0.0762"/>
            </geometry>
        </collision>
        <!-- <xacro:inertial_cylinder mass="0.05" length="0.0254" radius="0.0762"> -->
            <!-- origin should match visual origin -->
            <!-- <origin xyz="0 0 0" rpy="0 0 0"/>
        </xacro:inertial_cylinder> -->
    </link>

    <gazebo reference="back_right_wheel">
        <material>Gazebo/Gray</material>
    </gazebo>

    <!-- FRONT RIGHT WHEEL LINK -->

    <joint name="front_right_wheel_joint" type="continuous">
        <parent link="base_link"/>
        <child link="front_right_wheel"/>
        <origin xyz="-0.22733 -0.1143 0" rpy="1.5707963267948966 0 0" />
        <axis xyz="0 0 -1"/>
    </joint>

    <link name="front_right_wheel">
        <visual>
            <geometry>
                <cylinder radius="0.0762" length="0.0254"/>
            </geometry>
            <material name="gray"/>
        </visual>
        <collision>
            <geometry>
                <sphere radius="0.0762"/>
            </geometry>
        </collision>
        <!-- <xacro:inertial_cylinder mass="0.05" length="0.0254" radius="0.0762"> -->
            <!-- origin should match visual origin -->
            <!-- <origin xyz="0 0 0" rpy="0 0 0"/>
        </xacro:inertial_cylinder> -->
    </link>

    <gazebo reference="front_right_wheel">
        <material>Gazebo/Gray</material>
    </gazebo>
 
</robot>